Workbook

Sheet SOUTH
A2: REPUBLIC OF THE PHILIPPINES
A3: PROVINCIAL GOVERNMENT OF PALAWAN
A4: PROVICIAL ENGINEEING OFFICE
A5: CAPITOL COMPLEX, PUERTO PRINCESA CITY
A7: PROVINCIAL ROAD NETWORK AND ITS STATUS / CONDITION
A8: PRIORITY OF THE SCHEDULE OF REHAB FROM JULY 2025 - DECEMBER 2025
A9: SOUTH MUNICIPALITY OF PALAWAN
A11: NO. | B11: ROAD ID | C11: ROAD NAME | D11: 2024LENGTH (KM) | E11: LENGTH (KM) | F11: SURFACE TYPE (KM) | J11: ROAD CONDITION | K11: TOTAL KM OF PROVINCIAL ROAD NEED TO CONDUCT VEGETATION CONTROL(KM) | L11: TOTAL KM OF PROVINCIAL ROAD NEED TO REHAB(KM) | M11: with concreting | N11: NOTE | O11: KILOMETER POST
F12: CONCRETE | G12: ASPHALT | H12: EARTH | I12: GRAVEL
B13: MUNICIPALITY OF ABORLAN
A14: 1 | B14: 1 | C14: Sagpangan Road | D14: 3.47 | E14: ='[1]road inventory 2018'!C11 -> 5.5 | F14: 0 | G14: 0 | H14: 0 | I14: =D14-F14 -> 3.47 | J14: Good | K14: =SUM(F14:I14) -> 3.47 | L14: =SUM(G14:J14) -> 3.47 | M14: **exchange with Mailigan - Sagpangan | N14: km sta.66+400 | Q14: 23
A15: 2 | B15: 93 | C15: Iraan - Baraki Road | D15: 3.97 | E15: ='[1]road inventory 2018'!C15 -> 3.9 | F15: 3.69 | G15: 0 | H15: 0 | I15: =D15-F15 -> 0.28 | J15: Fair | K15: =SUM(F15:I15) -> 3.97 | L15: =SUM(G15:J15) -> 0.28 | N15: km sta.64+900 | O15: ok | Q15: 14
A16: 3 | B16: 4 | C16: Iraan - Tubig Road | D16: 2.77 | E16: ='[1]road inventory 2018'!C14 -> 2.7 | F16: 0.19 | G16: 0 | H16: 0 | I16: =D16-F16 -> 2.58 | J16: Fair | K16: =SUM(F16:I16) -> 2.77 | L16: =SUM(G16:J16) -> 2.58 | N16: km sta.64+900 | Q16: 13
A17: 4 | B17: 13 | C17: New Bantayan - Apis Road | D17: 1.75 | E17: ='[1]road inventory 2018'!C24 -> 1.7 | F17: 0 | G17: 0 | H17: 0 | I17: =D17-F17 -> 1.75 | J17: Poor | K17: =SUM(F17:I17) -> 1.75 | L17: =SUM(G17:J17) -> 1.75 | N17: km sta.69+200 | O17: ok | Q17: 7
A18: 5 | B18: 220 | C18: Tagbariri - Magsaysay Road | D18: 3 | E18: ='[1]road inventory 2018'!C26 -> 2.3 | F18: 0.325 | G18: 0 | H18: 0 | I18: =D18-F18 -> 2.675 | J18: Poor | K18: =SUM(F18:I18) -> 3 | L18: =SUM(G18:J18) -> 2.675 | N18: km sta.71+150 | O18: ok | Q18: 6
A19: 6 | B19: 12 | C19: Tagbariri Road | D19: 1.65 | E19: ='[1]road inventory 2018'!C25 -> 1.6 | F19: 0.86 | G19: 0 | H19: 0 | I19: =D19-F19 -> 0.79 | J19: Poor | K19: =SUM(F19:I19) -> 1.65 | L19: =SUM(G19:J19) -> 0.79 | N19: km sta.69+100 | O19: ok | Q19: 8
A20: 7 | B20: 16 | C20: Tigman - Caburian Road | D20: 1.028 | E20: ='[1]road inventory 2018'!C29 -> 1 | F20: 0 | G20: 0 | H20: 0 | I20: =D20-F20 -> 1.028 | J20: Fair | K20: =SUM(F20:I20) -> 1.028 | L20: =SUM(G20:J20) -> 1.028 | N20: km sta.78+150 | O20: ok | Q20: 5
A21: 8 | B21: 15 | C21: Tigman - Rizal Road | D21: 3.2 | E21: 3.2 | F21: 0 | G21: 0 | H21: 0 | I21: =D21-F21 -> 3.2 | J21: Poor | K21: =SUM(F21:I21) -> 3.2 | L21: =SUM(G21:J21) -> 3.2 | N21: km sta.77+400 | O21: NOT EXISTING | Q21: 4
A22: 9 | B22: 221 | C22: Hi-way Jct. Plaridel-Tigman-Caburian Rd | D22: 4.07 | E22: ='[1]road inventory 2018'!C32 -> 5.2 | F22: 1.56 | G22: 0 | H22: 0 | I22: =D22-F22 -> 2.51 | J22: Fair | K22: =SUM(F22:I22) -> 4.07 | L22: =SUM(G22:J22) -> 2.51 | N22: km sta.76+500 | O22: ok | Q22: 3
A23: 10 | B23: 10 | C23: Plaridel - Apis Cabigaan Road | D23: 13.9 | E23: ='[1]road inventory 2018'!C22 -> 13.6 | F23: 12.19 | G23: 0 | H23: 0 | I23: =D23-F23 -> 1.71 | J23: Good | K23: =SUM(F23:I23) -> 13.9 | L23: =SUM(G23:J23) -> 1.71 | N23: km sta.75+650 | Q23: 19
A24: 11 | B24: 218 | C24: Isaub - Sagpangan Road | D24: 4.77 | E24: ='[1]road inventory 2018'!C16 -> 5.8 | F24: 0 | G24: 0 | H24: 0 | I24: =D24-F24 -> 4.77 | J24: Fair | K24: =SUM(F24:I24) -> 4.77 | L24: =SUM(G24:J24) -> 4.77 | N24: km sta.58+000 | O24: ok | Q24: 21 | R24: SOUTH | S24: TOTAL MAINLAND
A25: 12 | B25: 2 | C25: Isaub - Marikit -Tubig Road | D25: 0.87 | E25: ='[1]road inventory 2018'!C12 -> 0.8 | F25: 0.43 | G25: 0 | H25: 0 | I25: =D25-F25 -> 0.44 | J25: Fair | K25: =SUM(F25:I25) -> 0.87 | L25: =SUM(G25:J25) -> 0.44 | N25: km sta.58+000 | Q25: 15
A26: 13 | B26: 5 | C26: PNAC Road | D26: 4.09 | E26: ='[1]road inventory 2018'!C17 -> 2.8 | F26: 3.537 | G26: 0 | H26: 0 | I26: =D26-F26 -> 0.553 | J26: Fair | K26: =SUM(F26:I26) -> 4.09 | L26: =SUM(G26:J26) -> 0.553 | M26: **exchange with San Juan Road | N26: km sta.64+900 | Q26: 12 | R26: =E38+#REF!+E59+E97+E132+E145+E152+E168 -> #REF! | S26: =R26+#REF! -> #REF!
A27: 14 | B27: 20 | C27: Aporawan-Daan-Cabigaan Road | D27: 7.668 | E27: ='[1]road inventory 2018'!C33 -> 7.6 | F27: 6.73 | G27: 0 | H27: 0 | I27: =D27-F27 -> 0.938 | J27: Good | K27: =SUM(F27:I27) -> 7.668 | L27: =SUM(G27:J27) -> 0.938
A28: 15 | B28: 219 | C28: Junction - Isaub Road | D28: 0.68 | E28: ='[1]road inventory 2018'!C10 -> 0.65 | F28: 0.68 | G28: 0 | H28: 0 | I28: =D28-F28 -> 0 | J28: Fair | K28: =SUM(F28:I28) -> 0.68 | L28: =SUM(G28:J28) -> 0 | N28: km sta.57+800 | O28: ok | Q28: 20
A29: 16 | B29: 3 | C29: Mailigan - Sagpangan Road | D29: 5.5 | E29: ='[1]road inventory 2018'!C13 -> 4.9 | F29: 5.5 | G29: 0 | H29: 0 | I29: =D29-F29 -> 0 | J29: Fair | K29: =SUM(F29:I29) -> 5.5 | L29: =SUM(G29:J29) -> 0 | M29: **exchange with Sagpangan Road | N29: km sta.62+400 | Q29: 22
A30: 17 | B30: 6 | C30: San Juan Road | D30: 2.67 | E30: ='[1]road inventory 2018'!C18 -> 3.9 | F30: 2.67 | G30: 0 | H30: 0 | I30: =D30-F30 -> 0 | J30: Good | K30: =SUM(F30:I30) -> 2.67 | L30: =SUM(G30:J30) -> 0 | M30: **exchange with PNAC | N30: km sta.66+400 | Q30: 11 | S30: =S26+#REF! -> #REF!
A31: 18 | B31: 7 | C31: Aborlan - River Landing | D31: 1.19 | E31: ='[1]road inventory 2018'!C19 -> 1.1 | F31: 1.19 | G31: 0 | H31: 0 | I31: =D31-F31 -> 0 | J31: Fair | K31: =SUM(F31:I31) -> 1.19 | L31: =SUM(G31:J31) -> 0 | N31: km sta.67+100 | O31: ok | Q31: 9
A32: 19 | B32: 8 | C32: Aborlan Poblacion Road | D32: 0.7 | E32: ='[1]road inventory 2018'!C20 -> 0.6 | F32: 0.7 | G32: 0 | H32: 0 | I32: =D32-F32 -> 0 | J32: Fair | K32: =SUM(F32:I32) -> 0.7 | L32: =SUM(G32:J32) -> 0 | N32: km sta.66+950 | O32: ok | Q32: 10
A33: 20 | B33: 9 | C33: Magbabadil - Cabigaan Road | D33: 9.1 | E33: ='[1]road inventory 2018'!C21 -> 9 | F33: 9.1 | G33: 0 | H33: 0 | I33: =D33-F33 -> 0 | J33: Good | K33: =SUM(F33:I33) -> 9.1 | L33: =SUM(G33:J33) -> 0 | N33: km sta.66+800 | P33: 8.646 | Q33: 18
A34: 21 | B34: 11 | C34: Tagpait Feeder Road | D34: 2.25 | E34: ='[1]road inventory 2018'!C23 -> 2.2 | F34: 2.25 | G34: 0 | H34: 0 | I34: =D34-F34 -> 0 | J34: Fair | K34: =SUM(F34:I34) -> 2.25 | L34: =SUM(G34:J34) -> 0 | N34: km sta.69+000 | O34: ok | Q34: 16
A35: 22 | B35: 14 | C35: Junction - Tigman Road | D35: 4.04 | E35: ='[1]road inventory 2018'!C27 -> 4 | F35: 4.04 | G35: 0 | H35: 0 | I35: =D35-F35 -> 0 | J35: Fair | K35: =SUM(F35:I35) -> 4.04 | L35: =SUM(G35:J35) -> 0 | N35: km sta.75+650 | O35: ok | Q35: 2
A36: 23 | B36: 17 | C36: Magbabadil - Baraki Road | D36: 4 | E36: ='[1]road inventory 2018'!C30 -> 4 | F36: 4 | G36: 0 | H36: 0 | I36: =D36-F36 -> 0 | J36: Good | K36: =SUM(F36:I36) -> 4 | L36: =SUM(G36:J36) -> 0 | N36: km sta.73+400 | O36: ok | P36: 1.422 | Q36: 17
A37: 24 | B37: 18 | C37: Tigman - Rizal - Dumangueña Road | D37: 10.58 | E37: ='[1]road inventory 2018'!C31 -> 10.5 | F37: 10.58 | G37: 0 | H37: 0 | I37: =D37-F37 -> 0 | J37: Fair | K37: =SUM(F37:I37) -> 10.58 | L37: =SUM(G37:J37) -> 0 | N37: km sta.77+400 | O37: cmgp 2019, 2kms | P37: ok | Q37: 1
C38: SUB-TOTAL | D38: =SUM(D14:D37) -> 96.916 | E38: =SUM(E28:E37) -> 40.85 | F38: =SUM(F14:F37) -> 70.222 | G38: =SUM(G14:G37) -> 0 | H38: =SUM(H14:H37) -> 0 | I38: =SUM(I14:I37) -> 26.694 | K38: =SUM(K14:K37) -> 96.916 | L38: =SUM(L14:L37) -> 26.694
B40: PROVINCIAL ROAD REHABILATION | D40: TOTAL LENGTH(KM) | F40: THICKNESS OF AGGREGATES NEEDED(M) | G40: WIDTH OF EMBANKMENT(M) | H40: APPROXIAMATE VOLUME NEEDED TO EMBANK THE AND CONDUCT REHAB
A41: 1 | B41: RIVER QUARRY/MOUNTAIN QUARRY | D41: =L38 -> 26.694 | F41: 0.1 | G41: 7 | H41: =D41*F41*1000*G41 -> 18685.8 | I41: CU.M | M41: =H41 -> 18685.8
B43: MUNICIPALITY OF BATARAZA
A44: 1 | B44: 80 | C44: Sandoval-Igang -Igang -Sarong Road | D44: 15.714 | E44: ='[1]road inventory 2018'!C154 -> 15.7 | F44: 2.57 | G44: 0 | H44: 0 | I44: =D44-F44 -> 13.144 | J44: Fair | K44: =SUM(F44:I44) -> 15.714 | L44: =SUM(G44:J44) -> 13.144 | N44: km sta.238+500 | O44: CARRIAGEWAY OKAY | P44: ok
A45: 2 | B45: 83 | C45: Sandoval Barak - Barakan Road | D45: 4.264 | E45: ='[1]road inventory 2018'!C157 -> 4.2 | F45: =0.328+0.091+0.13+0.039 -> 0.588 | G45: 0 | H45: 0 | I45: =D45-F45 -> 3.676 | J45: Fair | K45: =SUM(F45:I45) -> 4.264 | L45: =SUM(G45:J45) -> 3.676 | N45: km sta.238+500 | O45: CARRIAGEWAY OKAY | P45: ok
...

Sheet  road inventory 2024
B2: LIST OF PROVINCIAL ROAD NETWORK
B6: ROAD ID | C6: ROAD NAME | D6: LENGTH (KM) | E6: LENGTH (KM) | F6: SURFACE TYPE (KM) | J6: ROAD CONDITION
F7: CONCRETE | G7: ASPHALT | H7: EARTH | I7: GRAVEL
B8: MUNICIPALITY OF ABORLAN
A9: 1 | B9: 219 | C9: Junction - Isaub Road | D9: 0.68 | E9: ='[1]road inventory 2018'!C10 -> 0.65 | F9: 0.68 | G9: 0 | H9: 0 | I9: =D9-F9-G9-H9 -> 0 | J9: Fair
A10: 2 | B10: 1 | C10: Sagpangan Road | D10: 3.47 | E10: ='[1]road inventory 2018'!C11 -> 5.5 | F10: 0 | G10: 0 | H10: 0 | I10: =D10-F10-G10-H10 -> 3.47 | J10: Good
A11: 3 | B11: 2 | C11: Isaub - Marikit -Tubig Road | D11: 0.87 | E11: ='[1]road inventory 2018'!C12 -> 0.8 | F11: 0.43 | G11: 0 | H11: 0 | I11: =D11-F11-G11-H11 -> 0.44 | J11: Fair
A12: 4 | B12: 3 | C12: Mailigan - Sagpangan Road | D12: 5.5 | E12: ='[1]road inventory 2018'!C13 -> 4.9 | F12: 5.5 | G12: 0 | H12: 0 | I12: =D12-F12-G12-H12 -> 0 | J12: Fair
A13: 5 | B13: 4 | C13: Iraan - Tubig Road | D13: 2.77 | E13: ='[1]road inventory 2018'!C14 -> 2.7 | F13: 0.19 | G13: 0 | H13: 0 | I13: =D13-F13-G13-H13 -> 2.58 | J13: Fair
A14: 6 | B14: 93 | C14: Iraan - Baraki Road | D14: 3.97 | E14: ='[1]road inventory 2018'!C15 -> 3.9 | F14: 3.69 | G14: 0 | H14: 0 | I14: =D14-F14-G14-H14 -> 0.28 | J14: Fair
A15: 7 | B15: 218 | C15: Isaub - Sagpangan Road | D15: 4.77 | E15: ='[1]road inventory 2018'!C16 -> 5.8 | F15: 0 | G15: 0 | H15: 0 | I15: =D15-F15-G15-H15 -> 4.77 | J15: Fair
A16: 8 | B16: 5 | C16: PNAC Road | D16: 4.09 | E16: ='[1]road inventory 2018'!C17 -> 2.8 | F16: 3.537 | G16: 0 | H16: 0 | I16: =D16-F16-G16-H16 -> 0.553 | J16: Fair
A17: 9 | B17: 6 | C17: San Juan Road | D17: 2.67 | E17: ='[1]road inventory 2018'!C18 -> 3.9 | F17: 2.67 | G17: 0 | H17: 0 | I17: =D17-F17-G17-H17 -> 0 | J17: Good
A18: 10 | B18: 7 | C18: Aborlan - River Landing | D18: 1.19 | E18: ='[1]road inventory 2018'!C19 -> 1.1 | F18: 1.19 | G18: 0 | H18: 0 | I18: =D18-F18-G18-H18 -> 0 | J18: Fair
A19: 11 | B19: 8 | C19: Aborlan Poblacion Road | D19: 0.7 | E19: ='[1]road inventory 2018'!C20 -> 0.6 | F19: 0.7 | G19: 0 | H19: 0 | I19: =D19-F19-G19-H19 -> 0 | J19: Fair
A20: 12 | B20: 9 | C20: Magbabadil - Cabigaan Road | D20: 9.1 | E20: ='[1]road inventory 2018'!C21 -> 9 | F20: 9.1 | G20: 0 | H20: 0 | I20: =D20-F20-G20-H20 -> 0 | J20: Good
... A26: 18 | B26: 14 | C26: Junction - Tigman Road | D26: 4.04 | E26: ='[1]road inventory 2018'!C27 -> 4 | F26: 4.04 | G26: 0 | H26: 0 | I26: =D26-F26-G26-H26 -> 0 | J26: Fair
A27: 19 | B27: 15 | C27: Tigman - Rizal Road | D27: 3.2 | E27: 3.2 | F27: 0 | G27: 0 | H27: 0 | I27: =D27-F27-G27-H27 -> 3.2 | J27: Poor
A28: 20 | B28: 16 | C28: Tigman - Caburian Road | D28: 1.028 | E28: ='[1]road inventory 2018'!C29 -> 1 | F28: 0 | G28: 0 | H28: 0 | I28: =D28-F28-G28-H28 -> 1.028 | J28: Fair
A29: 21 | B29: 17 | C29: Magbabadil - Baraki Road | D29: 4 | E29: ='[1]road inventory 2018'!C30 -> 4 | F29: 4 | G29: 0 | H29: 0 | I29: =D29-F29-G29-H29 -> 0 | J29: Good
A30: 22 | B30: 18 | C30: Tigman - Rizal - Dumangueña Road | D30: 10.58 | E30: ='[1]road inventory 2018'!C31 -> 10.5 | F30: 10.58 | G30: 0 | H30: 0 | I30: =D30-F30-G30-H30 -> 0 | J30: Fair
A31: 23 | B31: 221 | C31: Hi-way Jct. Plaridel-Tigman-Caburian Rd | D31: 4.07 | E31: ='[1]road inventory 2018'!C32 -> 5.2 | F31: 1.56 | G31: 0 | H31: 0 | I31: =D31-F31-G31-H31 -> 2.51 | J31: Fair
A32: 24 | B32: 20 | C32: Aporawan-Daan-Cabigaan Road | D32: 7.668 | E32: ='[1]road inventory 2018'!C33 -> 7.6 | F32: =6.73+0.938 -> 7.668 | G32: 0 | H32: 0 | I32: =D32-F32-G32-H32 -> 0 | J32: Good
C33: SUB-TOTAL | D33: =SUM(D9:D32) -> 96.916 | E33: =SUM(E9:E32) -> 98.55 | F33: =SUM(F9:F32) -> 72.16 | G33: =SUM(G9:G32) -> 0 | H33: =SUM(H9:H32) -> 0 | I33: =SUM(I9:I32) -> 24.756
H34: =H33+I33 -> 24.756
B35: MUNICIPALITY OF BALABAC
A36: 1 | B36: 91 | C36: Balabac-Catagupan Road | D36: 10.809 | E36: ='[1]road inventory 2018'!C169 -> 12.9 | F36: 10.311 | G36: 0 | H36: 0 | I36: =D36-F36-G36-H36 -> 0.498 | J36: Fair
A37: 2 | B37: 92 | C37: Catagupan - Agutayan Road | D37: 8.067 | E37: ='[1]road inventory 2018'!C170 -> 5.6 | F37: 8.067 | G37: 0 | H37: 0 | I37: =D37-F37-G37-H37 -> 0 | J37: Fair
C38: SUB-TOTAL | D38: =SUM(D36:D37) -> 18.876 | E38: =SUM(E36:E37) -> 18.5 | F38: =SUM(F36:F37) -> 18.378 | G38: =SUM(G36:G37) -> 0 | H38: =SUM(H36:H37) -> 0 | I38: =SUM(I36:I37) -> 0.498
H39: =H38+I38 -> 0.498
B40: MUNICIPALITY OF BATARAZA
A41: 1 | B41: 95 | C41: a. Inogbong Sea Road | D41: 2.025 | E41: 2 | F41: 1.018 | G41: 0 | H41: 0 | I41: =D41-F41-G41-H41 -> 1.007 | J41: Fair
A42: 2 | C42: b. Inogbong Feeder Road | D42: 1.07 | E42: 1 | F42: 0.29 | G42: 0 | H42: 0 | I42: =D42-F42-G42-H42 -> 0.78 | J42: Poor
A43: 3 | B43: 77 | C43: Bataraza Poblacion Road | D43: 0.7 | E43: ='[1]road inventory 2018'!C150 -> 0.7 | F43: 0.7 | G43: 0 | H43: 0 | I43: =D43-F43-G43-H43 -> 0 | J43: Good
A44: 4 | B44: 94 | C44: Marangas Sea Road | D44: 0.634 | E44: ='[1]road inventory 2018'!C151 -> 0.6 | F44: 0 | G44: 0 | H44: 0 | I44: =D44-F44-G44-H44 -> 0.634 | J44: Fair
A45: 5 | B45: 78 | C45: Marangas Feeder Road | D45: 3.91 | E45: ='[1]road inventory 2018'!C152 -> 3.8 | F45: 0.708 | G45: 0 | H45: 0 | I45: =D45-F45-G45-H45 -> 3.202 | J45: Fair
A46: 6 | B46: 79 | C46: Iniam - Bono-bono Road | D46: 1.943 | E46: ='[1]road inventory 2018'!C153 -> 1.9 | F46: 0.12 | G46: 0 | H46: 0 | I46: =D46-F46-G46-H46 -> 1.823 | J46: Poor
A47: 7 | B47: 80 | C47: Sandoval-Igang -Igang -Sarong Road | D47: 15.714 | E47: ='[1]road inventory 2018'!C154 -> 15.7 | F47: 2.57 | G47: 0 | H47: 0 | I47: =D47-F47-G47-H47 -> 13.144 | J47: Fair
A48: 8 | B48: 81 | C48: Ocayan Road | D48: 3.9 | E48: ='[1]road inventory 2018'!C155 -> 3.8 | F48: =0.23+3.33 -> 3.56 | G48: 0 | H48: 0 | I48: =D48-F48-G48-H48 -> 0.34 | J48: Poor
A49: 9 | B49: 82 | C49: Taratak Sea Road | D49: 5.42 | E49: ='[1]road inventory 2018'!C156 -> 5.4 | F49: =3.12 -> 3.12 | G49: 0 | H49: 0.404 | I49: =D49-F49-G49-H49 -> 1.896 | J49: Good
...

Sheet UPDATED (FOR PRINTING) (2)
B1: PROVINCIAL ENGINEER'S OFFICE
B2: PROVINCIAL ROAD NETWORK AND ITS STATUS / CONDITION
B3: AS OF NOVEMBER 15, 2021
B6: MUNICIPALITY OF ABORLAN | R6: SOUTH | T6: NORTH | V6: ISLANDS
R7: =D34+D70+D87+D95+D111+D153+D175 -> 449.99 | T7: =D212+D246+D259+D283 -> 350.26 | V7: =D184+D317+D340+D370+D385+D399 -> 279.914
B8: ROAD ID | C8: ROAD NAME | D8: REVISED LENGTH (km/s.) | E8: OLD LENGTH | F8: SURFACE TYPE | K8: ROAD CONDITION | L8: KILOMETER POST | M8: REMARKS
F9: CONCRETE | G9: ASPHALT | H9: EARTH | I9: GRAVEL | J9: MIXED | Q9: TOTAL | R9: =R7+T7+V7 -> 1080.164 | T9: =R13-R9 -> 156.301 | V9: =(R9/R13)*100 -> 87.359044
A10: 1 | B10: 219 | C10: Junction - Isaub Road | D10: =SUM(F10:J10) -> 0.4 | E10: ='[1]road inventory 2018'!C10 -> 0.65 | F10: 0.25 | G10: 0 | H10: 0 | I10: 0.15 | J10: 0 | K10: FAIR | L10: km sta.57+800 | O10: =D10 -> 0.4 | Q10: New
A11: 2 | B11: 1 | C11: Sagpangan Road | D11: =SUM(F11:J11) -> 5.48 | E11: ='[1]road inventory 2018'!C11 -> 5.5 | F11: 4.88 | G11: 0 | H11: 0 | I11: 0.6 | J11: 0 | K11: GOOD | L11: km sta.66+400 | O11: =D11 -> 5.48 | Q11: Good | R11: =E34+E70+E87+E94+E111+E153+E175 -> 454.25 | T11: =E212+E231+E246+E259+E283 -> 417.85 | V11: =E184+E302+E317+E340+E370+E385+E399+D405 -> 364.365
A12: 3 | B12: 2 | C12: Isaub - Marikit -Tubig Road | D12: =+F12+G12+I12+H12 -> 0.92 | E12: ='[1]road inventory 2018'!C12 -> 0.8 | F12: 0.07 | G12: 0 | H12: 0 | I12: 0.85 | J12: 0 | K12: FAIR | L12: km sta.58+000 | O12: =D12 -> 0.92 | Q12: Fair
A13: 4 | B13: 3 | C13: Mailigan - Sagpangan Road | D13: =SUM(F13:J13) -> 4.97 | E13: ='[1]road inventory 2018'!C13 -> 4.9 | F13: 0 | G13: 0 | H13: 0 | I13: 4.97 | J13: 0 | K13: FAIR | L13: km sta.62+400 | N13: X | O13: =D13 -> 4.97 | Q13: Poor | R13: =R11+T11+V11 -> 1236.465
A14: 5 | B14: 4 | C14: Iraan - Tubig Road | D14: =+F14+G14+I14+H14 -> 2.67 | E14: ='[1]road inventory 2018'!C14 -> 2.7 | F14: 0 | G14: 0 | H14: 0 | I14: 2.67 | J14: 0 | K14: FAIR | L14: km sta.64+900 | N14: X | O14: =D14 -> 2.67 | Q14: Bad
A15: 6 | B15: 93 | C15: Iraan - Baraki Road | D15: =+F15+G15+I15+H15 -> 3.9 | E15: ='[1]road inventory 2018'!C15 -> 3.9 | F15: 3.79 | G15: 0 | H15: 0 | I15: 0.11 | J15: 0 | K15: FAIR | L15: km sta.64+900 | O15: =D15 -> 3.9 | R15: =E302+E309+E314+E326+E331+E335+E336+E338+E349+E358+E363+E365+E368+E381+E382+E383+E384 -> 175.06 | T15: =T9-R15 -> -18.759
A16: 7 | B16: 218 | C16: Isaub - Sagpangan Road | D16: =SUM(F16:J16) -> 5.61 | E16: ='[1]road inventory 2018'!C16 -> 5.8 | F16: 0 | G16: 0 | H16: 0 | I16: 5.61 | J16: 0 | K16: FAIR | L16: km sta.58+000 | O16: =D16 -> 5.61
A17: 8 | B17: 5 | C17: PNAC Road | D17: =SUM(F17:J17) -> 2.85 | E17: ='[1]road inventory 2018'!C17 -> 2.8 | F17: 2.85 | G17: 0 | H17: 0 | I17: 0 | J17: 0 | K17: FAIR | L17: km sta.64+900 | O17: =D17 -> 2.85 | R17: =E28+E47+E52+E82+T67 -> 8.47
A18: 9 | B18: 6 | C18: San Juan Road | D18: =+F18+G18+I18+H18 -> 3.96 | E18: ='[1]road inventory 2018'!C18 -> 3.9 | F18: =2.6+0.9 -> 3.5 | G18: 0 | H18: 0 | I18: 0.46 | J18: 0 | K18: GOOD | L18: km sta.66+400 | O18: =D18 -> 3.96
A19: 10 | B19: 7 | C19: Aborlan - River Landing | D19: 1.15 | E19: ='[1]road inventory 2018'!C19 -> 1.1 | F19: 1.15 | G19: 0 | H19: 0 | I19: 0 | J19: 0 | K19: FAIR | L19: km sta.67+100 | O19: =D19 -> 1.15 | Q19: GOOD TO FAIR (TOTAL LENGTH) | T19: ACTUAL
A20: 11 | B20: 8 | C20: Aborlan Poblacion Road | D20: =SUM(F20:J20) -> 0.64 | E20: ='[1]road inventory 2018'!C20 -> 0.6 | F20: 0.64 | G20: 0 | H20: 0 | I20: 0 | J20: 0 | K20: FAIR | L20: km sta.66+950 | O20: =D20 -> 0.64 | Q20: ABORLAN | R20: =D10+D11+D12+D13+D15+D16+D17+D18+D19+D20+D21+D22+D23+D24+D27+D29+D30+D31+D32 -> 81.36 | T20: =R20 -> 81.36
A21: 12 | B21: 9 | C21: Magbabadil - Cabigaan Road | D21: =+F21+G21+I21+H21 -> 9.3 | E21: ='[1]road inventory 2018'!C21 -> 9 | F21: 9.3 | G21: 0 | H21: 0 | I21: 0 | J21: 0 | K21: GOOD | L21: km sta.66+800 | O21: =D21 -> 9.3 | Q21: NARRA | R21: =D43+D44+D45+D46+D47+D48+D49+D50+D51+D52+D53++D54+D57+D58+D59+D60+D61+D62+D63+D66+D69 -> 72.35 | T21: =R21 -> 72.35
A22: 13 | B22: 10 | C22: Plaridel - Apis Cabigaan Road | D22: =SUM(F22:J22) -> 13.79 | E22: ='[1]road inventory 2018'!C22 -> 13.6 | F22: =8.47+1.31+0.34 -> 10.12 | G22: 0 | H22: 0 | I22: 3.67 | J22: 0 | K22: GOOD | L22: km sta.75+650 | O22: =D22 -> 13.79 | Q22: QUEZON | R22: =D80+D81+D82+D83+D84+D85 -> 28.02 | T22: =R22 -> 28.02
A23: 14 | B23: 11 | C23: Tagpait Feeder Road | D23: =SUM(F23:J23) -> 2.27 | E23: ='[1]road inventory 2018'!C23 -> 2.2 | F23: 1.3 | G23: 0 | H23: 0 | I23: 0.97 | J23: 0 | K23: FAIR | L23: km sta.69+000 | O23: =D23 -> 2.27 | Q23: RIZAL | R23: =D94 -> 3.28 | T23: =R23 -> 3.28
A24: 15 | B24: 13 | C24: New Bantayan - Apis Road | D24: =SUM(F24:J24) -> 1.72 | E24: ='[1]road inventory 2018'!C24 -> 1.7 | F24: 0 | G24: 0 | H24: 0 | I24: 1.72 | J24: 0 | K24: POOR | L24: km sta.69+200 | O24: =D24 -> 1.72 | Q24: ESPANOLA | R24: =D102+D104+D105+D106+D107+D108 -> 26.3 | T24: =R24 -> 26.3
A25: 16 | B25: 12 | C25: Tagbariri Road | D25: =+F25+G25+I25+H25 -> 1.62 | E25: ='[1]road inventory 2018'!C25 -> 1.6 | F25: 0 | G25: 0 | H25: 0 | I25: 1.62 | J25: 0 | K25: POOR | L25: km sta.69+100 | O25: =D25 -> 1.62 | Q25: BROOKES POINT | R25: =D119+D120+D121+D122+D123+D124+D125+D126+D127+D130+D131+D132+D133+D134+D135+D136+D137+D138+D139+D140+D143+D146+D147+D148+D149+D151+D152 -> 107.48 | T25: =R25 -> 107.48
A26: 17 | B26: 220 | C26: Tagbariri - Magsaysay Road | D26: =SUM(F26:J26) -> 2.11 | E26: ='[1]road inventory 2018'!C26 -> 2.3 | F26: 0 | G26: 0 | H26: 0 | I26: 2.11 | J26: 0 | K26: POOR | L26: km sta.71+150 | O26: =D26 -> 2.11 | Q26: BATARAZA | R26: =D161+D162+D163+D169+D171 -> 10.66 | T26: =R26 -> 10.66
A27: 18 | B27: 14 | C27: Junction - Tigman Road | D27: =SUM(F27:J27) -> 4.12 | E27: ='[1]road inventory 2018'!C27 -> 4 | F27: 4.12 | G27: 0 | H27: 0 | I27: 0 | J27: 0 | K27: FAIR | L27: km sta.75+650 | O27: =D27 -> 4.12 | Q27: BALABAC | R27: =D182+D183 -> 18.49 | T27: =R27 -> 18.49
A28: 19 | B28: 15 | C28: Tigman - Rizal Road | D28: 0 | E28: 0 | F28: 0 | G28: 0 | H28: 0 | I28: 0 | J28: 0 | K28: Poor | L28: km sta.77+400 | M28: NOT EXISTING | O28: =D28 -> 0 | Q28: ROXAS | R28: =D193+D194+D197+D199+D200+D201+D204+D203+D207+D208+D209+D210+D211 -> 108.29 | T28: =R28 -> 108.29
A29: 20 | B29: 16 | C29: Tigman - Caburian Road | D29: =SUM(F29:J29) -> 1.05 | E29: ='[1]road inventory 2018'!C29 -> 1 | F29: 0 | G29: 0 | H29: 0 | I29: 1.05 | J29: 0 | K29: FAIR | L29: km sta.78+150 | O29: =D29 -> 1.05 | Q29: SANVICENTE | R29: =D223+D224+D226+D227+D229+D230 -> 77.27 | T29: =R29 -> 77.27
A30: 21 | B30: 17 | C30: Magbabadil - Baraki Road | D30: =SUM(F30:J30) -> 4.18 | E30: ='[1]road inventory 2018'!C30 -> 4 | F30: 4.18 | G30: 0 | H30: 0 | I30: 0 | J30: 0 | K30: GOOD | L30: km sta.73+400 | O30: =D30 -> 4.18 | Q30: TAYTAY | R30: =D238+D239+D240+D241+D243+D244+D245 -> 88.47 | T30: =R30 -> 88.47
A31: 22 | B31: 18 | C31: Tigman - Rizal - Dumangueña Road | D31: =+F31+G31+I31+H31 -> 10.52 | E31: ='[1]road inventory 2018'!C31 -> 10.5 | F31: =4.2+3.15+0.2+0.88+0.6 -> 9.03 | G31: 0 | H31: 0 | I31: 1.49 | J31: 0 | K31: FAIR | L31: km sta.77+400 | O31: =D31 -> 10.52 | Q31: EL NIDO | R31: =D255+D257 -> 9.09 | T31: =R31 -> 9.09
A32: 23 | B32: 221 | C32: Hi-way Jct. Plaridel-Tigman-Caburian Rd | D32: =+F32+G32+I32+H32 -> 4.53 | E32: ='[1]road inventory 2018'!C32 -> 5.2 | F32: 1.17 | G32: 0 | H32: 0 | I32: 3.36 | J32: 0 | K32: FAIR | L32: km sta.76+500 | O32: =D32 -> 4.53 | Q32: DUMARAN | R32: =D266+D267+D268+D272+D273+D276+D277+D281+D282 -> 65.27 | T32: =R32 -> 65.27
A33: 24 | B33: 20 | C33: Aporawan-Daan-Cabigaan Road | D33: =+F33+G33+I33+H33+J33 -> 7.63 | E33: ='[1]road inventory 2018'!C33 -> 7.6 | F33: 1.9 | G33: 0 | H33: 0 | I33: 1.2 | J33: 4.53 | K33: BAD | O33: =D33 -> 7.63 | Q33: ARACELI | R33: =D292+D297+D298 -> 10.1 | T33: 0
D34: =SUM(D10:D33) -> 95.39 | E34: =SUM(E10:E33) -> 95.35 | F34: =SUM(F10:F33) -> 58.25 | G34: =G32+G31+G30+G29+G27+G26+G24+G23+G22+G21+G20+G19+G17+G16+G13+G11+G10 -> 0 | H34: =H32+H31+H30+H29+H27+H26+H24+H23+H22+H21+H20+H19+H17+H16+H13+H11+H10 -> 0 | I34: =SUM(I10:I33) -> 32.61 | J34: =J32+J31+J30+J29+J27+J26+J24+J23+J22+J21+J20+J19+J17+J16+J13+J11+J10 -> 0 | P34: =SUM(O10:O33) -> 95.39 | Q34: CUYO | R34: =D309+D310+D312+D313+D315 -> 27.062 | T34: =D310+D312+D313+D315 -> 14.362
B35: SUB-TOTAL | D35: =F35+G35+H35+I35+J35 -> 95.39 | F35: =SUM(F10:F33) -> 58.25 | G35: =SUM(G10:G33) -> 0 | H35: =SUM(H10:H33) -> 0 | I35: =SUM(I10:I33) -> 32.61 | J35: =SUM(J10:J33) -> 4.53 | Q35: MAGSAYSAY | R35: =D327+D328+D329+D330+D338+D339 -> 10.64 | T35: =D327+D328+D329+D330+D339 -> 9.84
Q36: AGUTAYA | R36: =D347+D348 -> 7.25 | T36: 0
B39: MUNICIPALITY OF NARRA | Q39: CORON | R39: =D357+D359+D360+D361+D362+D365+D366+D367+D369 -> 79.645 | T39: =D357+D359+D360+D361+D362+D366+D367+D369 -> 77.225
Q40: BUSUANGA | R40: =D379+D380+D382+D383 -> 34.028 | T40: =D379+D380 -> 13.028
B41: ROAD ID | C41: ROAD NAME | D41: LENGTH (km/s.) | F41: SURFACE TYPE | K41: ROAD CONDITION | L41: KILOMETER POST | M41: REMARKS | Q41: CULION | R41: =D392+D393+D394+D398 -> 20.704 | T41: =D392+D393+D394+D398 -> 20.704
F42: CONCRETE | G42: ASPHALT | H42: EARTH | I42: GRAVEL | J42: MIXED | Q42: CAGAYAN CILLO | R42: =D405 -> 8.741 | T42: 0
A43: 1 | B43: 21 | C43: Sandoval Feeder Road | D43: =+F43+G43+I43 -> 4.32 | E43: ='[1]road inventory 2018'!C41 -> 4.3 | F43: 4.32 | G43: 0 | H43: 0 | I43: 0 | J43: 0 | K43: GOOD | L43: km sta.79+500 | O43: =D43 -> 4.32 | Q43: =Q19 -> GOOD TO FAIR (TOTAL LENGTH) | R43: =SUM(R20:R42) -> 894.5 | S43: =D410-R43 -> 352.415 | T43: =SUM(T20:T42) -> 831.489
A44: 2 | B44: 22 | C44: Apo-Aporawan Section Road | D44: =+F44+G44+I44 -> 4.01 | E44: ='[1]road inventory 2018'!C42 -> 3.9 | F44: 0 | G44: 0 | H44: 0 | I44: 4.01 | J44: 0 | K44: POOR | L44: km sta.80+770 | O44: =D44 -> 4.01
...

Sheet GRAPH
J1: GOOD | L1: C | M1: A | N1: E | O1: G | P1: M
C2: R O A D I N V E N T O R Y
C4: CONCRETE | D4: ASPHALT | E4: EARTH | F4: GRAVEL | I4: 1 | J4: Sagpangan Road | K4: 5.48 | L4: 4.88 | M4: 0 | N4: 0 | O4: 0.6 | P4: 0 | Q4: GOOD | R4: km sta.66+400 | W4: CONCRETE | X4: ASPHALT | Y4: EARTH | Z4: GRAVEL | AA4: MIXED | AC4: GOOD TO FAIR | AD4: : | AE4: =(C5+E5+D5+F5+G5)+(C6+D6+E6+F6+G6) -> 927.6132
B5: GOOD | C5: ='SUMMARY 2021'!K45 -> 221.1882 | D5: ='SUMMARY 2021'!L45 -> 2.083 | E5: ='SUMMARY 2021'!M45 -> 3.42 | F5: ='SUMMARY 2021'!N45 -> 76.466 | H5: =SUM(C5:G5) -> 303.1572 | I5: 6 | J5: San Juan Road | K5: 3.96 | L5: 3.5 | M5: 0 | N5: 0 | O5: 0.46 | P5: 0 | Q5: GOOD | R5: km sta.66+400 | W5: =C5*15000000 -> 3.317823e+09 | X5: =D5*100000 -> 208300 | Y5: =E5*100000 -> 342000 | Z5: =F5*100000 -> 7646600 | AA5: =G5*100000 -> 0 | AC5: POOR TO BAD | AD5: : | AE5: =(C7+D7+E7+F7+G7)+(C8+D8+E8+F8+G8) -> 301.938
B6: FAIR | C6: ='SUMMARY 2021'!K46 -> 171.764 | D6: ='SUMMARY 2021'!L46 -> 0 | E6: ='SUMMARY 2021'!M46 -> 1.72 | F6: ='SUMMARY 2021'!N46 -> 450.972 | H6: =SUM(C6:G6) -> 624.456 | I6: 9 | J6: Magbabadil - Cabigaan Road | K6: 9.3 | L6: 9.3 | M6: 0 | N6: 0 | O6: 0 | P6: 0 | Q6: GOOD | R6: km sta.66+800 | W6: =C6*15000000 -> 2.57646e+09 | X6: =D6*100000 -> 0 | Y6: =E6*100000 -> 172000 | Z6: =F6*100000 -> 45097200 | AA6: =G6*100000 -> 0 | AC6: TOTAL LENGTH | AD6: : | AE6: =AE4+AE5 -> 1229.5512
B7: POOR | C7: ='SUMMARY 2021'!K47 -> 33.224 | D7: ='SUMMARY 2021'!L47 -> 2.55 | E7: ='SUMMARY 2021'!M47 -> 0 | F7: ='SUMMARY 2021'!N47 -> 149.181 | H7: =SUM(C7:G7) -> 184.955 | I7: 10 | J7: Plaridel - Apis Cabigaan Road | K7: 13.79 | L7: 10.12 | M7: 0 | N7: 0 | O7: 3.67 | P7: 0 | Q7: GOOD | R7: km sta.75+650 | W7: =C7*15000000 -> 4.9836e+08 | X7: =D7*100000 -> 255000 | Y7: =E7*100000 -> 0 | Z7: =F7*100000 -> 14918100 | AA7: =G7*100000 -> 0
B8: BAD | C8: ='SUMMARY 2021'!K48 -> 14.332 | D8: ='SUMMARY 2021'!L48 -> 6.11 | E8: ='SUMMARY 2021'!M48 -> 5.544 | F8: ='SUMMARY 2021'!N48 -> 90.997 | H8: =SUM(C8:G8) -> 116.983 | I8: 17 | J8: Magbabadil - Baraki Road | K8: 4.18 | L8: 4.18 | M8: 0 | N8: 0 | O8: 0 | P8: 0 | Q8: GOOD | R8: km sta.73+400 | W8: =C8*15000000 -> 214980000 | X8: =D8*100000 -> 611000 | Y8: =E8*100000 -> 554400 | Z8: =F8*100000 -> 9099700 | AA8: =G8*100000 -> 0
C9: =SUM(C5:C8) -> 440.5082 | D9: =SUM(D5:D8) -> 10.743 | E9: =SUM(E5:E8) -> 10.684 | F9: =SUM(F5:F8) -> 767.616 | G9: =SUM(C9:F9) -> 1229.5512 | H9: =SUM(H5:H8) -> 1229.5512 | I9: 21 | J9: Sandoval Feeder Road | K9: 4.32 | L9: 4.32 | M9: 0 | N9: 0 | O9: 0 | P9: 0 | Q9: GOOD | R9: km sta.79+500 | W9: =SUM(W5:W8) -> 6607623000 | X9: =SUM(X5:X8) -> 1074300 | Y9: =SUM(Y5:Y8) -> 1068400 | Z9: =SUM(Z5:Z8) -> 76761600 | AA9: =SUM(AA5:AA8) -> 0 | AB9: =SUM(W9:AA9) -> 6686527300
H10: =SUM(C9:G9) -> 2459.1024 | I10: 26 | J10: Taritien Section Road | K10: 6.06 | L10: 3.81 | M10: 0 | N10: 0 | O10: 2.25 | P10: 0 | Q10: GOOD | R10: km sta.85+500
I11: 30 | J11: Rizal Avenue Section Road | K11: 0 | L11: 0 | M11: 0 | N11: 0 | O11: 0 | P11: 0 | Q11: Good | R11: km sta.91+670 | S11: MUNICIPAL ROAD
I12: 106 | J12: Narra Panacan Road | K12: 3.21 | L12: 3.21 | M12: 0 | N12: 0 | O12: 0 | P12: 0 | Q12: GOOD | R12: km sta.92+370
I13: 40 | J13: Calategas Sea Road | K13: 1.55 | L13: 1.1 | M13: 0 | N13: 0 | O13: 0.45 | P13: 0 | Q13: GOOD | R13: km sta.115+010
I14: 101 | J14: Magsaysay Road | K14: 0 | L14: 0 | M14: 0 | N14: 0 | O14: 0 | P14: 0 | Q14: Good | R14: km sta.146+000 | S14: MUNICIPAL ROAD
I15: 217 | J15: Punang Plain Road | K15: 1.14 | L15: 1.14 | M15: 0 | N15: 0 | O15: 0 | P15: 0 | Q15: GOOD | R15: km sta.149+200
I16: 226 | J16: Pulot Sea Road | K16: 4.01 | L16: 0.86 | M16: 0 | N16: 0 | O16: 3.15 | P16: 0 | Q16: GOOD | R16: km sta.162+800 | V16: =(C9/$AE$6)*100 -> 35.826747 | AC16: %
I17: 46 | J17: Pulot Bo. High School Road | K17: 1.3 | L17: 1.3 | M17: 0 | N17: 0 | O17: 0 | P17: 0 | Q17: GOOD | R17: km sta.163+800 | V17: =(D9/$AE$6)*100 -> 0.87373344 | AC17: %
I18: 54 | J18: Ipilan Sea Road | K18: 1.69 | L18: 1.18 | M18: 0 | N18: 0 | O18: 0.51 | P18: 0 | Q18: GOOD | R18: km sta.180+700 | V18: =(E9/$AE$6)*100 -> 0.86893494 | AC18: %
I19: 60 | J19: Junction Mainit Road | K19: 9.2 | L19: 7.1 | M19: 0 | N19: 0 | O19: 2.1 | P19: 0 | Q19: GOOD | R19: km sta.189+95 | V19: =(F9/$AE$6)*100 -> 62.430584 | AC19: %
I20: 98 | J20: Calasaguen Feeder Road | K20: 4.98 | L20: 4.98 | M20: 0 | N20: 0 | O20: 0 | P20: 0 | Q20: GOOD | R20: km sta.168+75 | V20: =SUM(V16:V19) -> 100 | AC20: %
I21: 64 | J21: Calasaguen Abubakar Road | K21: 3.64 | L21: 3.64 | M21: 0 | N21: 0 | O21: 0 | P21: 0 | Q21: GOOD | R21: km sta.170+750 | AC21: %
I22: 77 | J22: Bataraza Poblacion Road | K22: 0.76 | L22: 0 | M22: 0 | N22: 0 | O22: 0.76 | P22: 0 | Q22: GOOD | R22: km sta.216+720
I23: 94 | J23: Marangas Sea Road | K23: 0.6 | L23: 0 | M23: 0 | N23: 0 | O23: 0.6 | P23: 0 | Q23: GOOD | R23: km sta.217+260
I24: 91 | J24: Balabac-Catagupan Road | K24: 12.89 | L24: 12.21 | M24: 0 | N24: 0 | O24: 0.68 | P24: 0 | Q24: GOOD | R24: km sta.000-sta.12+900 | AF24: STEEL TRUSS
I25: 89 | J25: Highway Junction Tinitian Road | K25: 0.63 | L25: 0.3 | M25: 0 | N25: 0 | O25: 0.33 | P25: 0 | Q25: GOOD | R25: km sta.92+700 | AF25: PNAC Road | AG25: 67+450 | AH25: 45 | AI25: Steel Truss | AJ25: Good
I26: 109 | J26: Highway Junction Caramay Road | K26: 2.5 | L26: 0.257 | M26: 0 | N26: 0 | O26: 2.243 | P26: 0 | Q26: GOOD | R26: km sta.107+900 | AF26: Tigman - Caburian Road | AG26: 78+830 | AH26: 26 | AI26: Steel Truss | AJ26: Good
I27: 115 | J27: San Jose Port Barton Road - A | K27: 10.71 | L27: 10.71 | M27: 0 | N27: 0 | O27: 0 | P27: 0 | Q27: GOOD | R27: km sta.124+600 | AF27: Tigman - Rizal - Dumangueña Road | AH27: 44 | AI27: Steel Truss | AJ27: Good
I28: 132 | J28: Highway Junction Tumarbong Road | K28: 13.5 | L28: 8.82 | M28: 0 | N28: 0 | O28: 4.68 | P28: 0 | Q28: GOOD | R28: km sta.150+400 | AF28: Balabac-Catagupan Road | AG28: 11+911 | AH28: 25 | AI28: Steel Truss | AJ28: Good
C29: B R I D G E I N V E N T O R Y | I29: 136 | J29: Canadcan - Alimanguan Road | K29: 11.31 | L29: 8.7 | M29: 0 | N29: 0 | O29: 2.61 | P29: 0 | Q29: GOOD | R29: km sta.171+800
I30: 137 | J30: Alimanguan - Kemdeng Road | K30: 12.59 | L30: 8.74 | M30: 0 | N30: 0 | O30: 3.85 | P30: 0 | Q30: GOOD | R30: km sta.183+100
D31: STEEL TRUSS | E31: BAILEY | F31: RC. GIRDER | G31: TIMBER | I31: 120 | J31: San Jose - Port Barton Road -B | K31: 10.85 | L31: 10.24 | M31: 0 | N31: 0 | O31: 0.61 | P31: 0 | Q31: GOOD | R31: km sta.135+400 | AF31: Malinao Feeder Road | AG31: Presidential Bridge | AH31: 29 | AI31: Steel Truss | AJ31: Fair
C32: GOOD | D32: =AH26+AH27+AH28+AH25 -> 140 | E32: =AH36+AH37 -> 78 | F32: =SUM(AH56:AH104) -> 919.88 | G32: 0 | I32: 126 | J32: Paglaum - Itangil Road | K32: 9.95 | L32: 9.95 | M32: 0 | N32: 0 | O32: 0 | P32: 0 | Q32: GOOD | R32: km sta.194+900
C33: FAIR | D33: =AH31 -> 29 | E33: =AH39+AH40+AH41 -> 69 | F33: =SUM(AH106:AH128) -> 507.6 | G33: =SUM(AH137:AH144) -> 143 | I33: 147 | J33: Taytay - Sta. Cruz Road | K33: 4.59 | L33: 0.2 | M33: 0 | N33: 0 | O33: 4.39 | P33: 0 | Q33: GOOD
C34: POOR | D34: =L243 -> 0 | E34: =SUM(AH43:AH49) -> 195.1 | F34: =SUM(AH131:AH133) -> 113.4 | G34: =SUM(AH147:AH155) -> 114.5 | I34: 150 | J34: New Ibajay - Lamoro Road | K34: 11.27 | L34: 5.87 | M34: 0 | N34: 0 | O34: 5.4 | P34: 0 | Q34: GOOD | R34: km sta.356+000-sta.368+300 | AF34: BAILEY
C35: BAD | D35: =L268 -> 0 | E35: =AH52+1 -> 17 | F35: =N268 -> 0 | G35: =AH157 -> 5 | I35: 127 | J35: Junction Bantal - San Jose Road | K35: 2.7 | L35: 1.29 | M35: 0 | N35: 0.9 | O35: 0.51 | P35: 0 | Q35: GOOD | R35: km sta.229+320 | V35: =SUM(D36:G36) -> 2331.48
D36: =SUM(D32:D35) -> 169 | E36: =SUM(E32:E35) -> 359.1 | F36: =SUM(F32:F35) -> 1540.88 | G36: =SUM(G32:G35) -> 262.5 | I36: 128 | J36: Junction Salogon - Danleg Road | K36: 2.3 | L36: 2.3 | M36: 0 | N36: 0 | O36: 0 | P36: 0 | Q36: GOOD | R36: km sta.230+070 | AC36: ln.m | AG36: 364+850 | AH36: 33 | AI36: Bailey | AJ36: Good
I37: 197 | J37: Jct. Cuyo- Suba-Baayad Road | K37: 4.927 | L37: 3.094 | M37: 1.833 | N37: 0 | O37: 0 | P37: 0 | Q37: GOOD | R37: km sta.26+530 | AF37: Bucana - Duli Road | AH37: 45 | AI37: Bailey | AJ37: Good
I38: 200 | J38: Cuyo Catadman Road | K38: 1.1 | L38: 1.1 | M38: 0 | N38: 0 | O38: 0 | P38: 0 | Q38: GOOD | R38: km sta.0+320
I39: 201 | J39: Lungsod Balaguen Road A | K39: 2.7 | L39: 2.7 | M39: 0 | N39: 0 | O39: 0 | P39: 0 | Q39: GOOD | R39: km sta.1+000 | AG39: Guadalupe Bridge 2 | AH39: 18 | AI39: Bailey | AJ39: Fair
I40: 202 | J40: Lungsod - Igabas - Emilod Road-A | K40: 1.37 | L40: 1.37 | M40: 0 | N40: 0 | O40: 0 | P40: 0 | Q40: GOOD | R40: km sta.1+000 | AF40: Balala - Malaking Patag Road | AG40: Malaking Patag Bridge | AH40: 30 | AI40: Bailey | AJ40: Fair
I41: 203 | J41: Maringian - Danawan Road | K41: 5.635 | L41: 2.535 | M41: 1.45 | N41: 0 | O41: 1.65 | P41: 0 | Q41: GOOD | R41: km sta.3+500 | AF41: Cabulihan Malaking Patag Road | AG41: Malaking Patag Bridge | AH41: 21 | AI41: Bailey | AJ41: Fair
...

Sheet SUMMARY 2021
A1: PROVINCIAL ENGINEER'S OFFICE
A2: PROVINCIAL ROAD NETWORK AND ITS STATUS / CONDITION
A3: 2021
A5: SUMMARY OF ROAD SURFACE
A7: NO | B7: MUNICIPALITY | C7: NO. OF PROVINCIAL ROAD | D7: TOTAL LENGTH (KM) | E7: CONCRETE (KM) | F7: ASPHALT (KM) | G7: EARTH (KM) | H7: GRAVEL (KM)
A8: 1 | B8: Aborlan | C8: 24 | D8: =SUM(E8:H8) -> 98.55 | E8: ='inventory2022 (FINAL)'!F32 -> 56.048 | F8: ='inventory2022 (FINAL)'!G32 -> 0 | G8: ='inventory2022 (FINAL)'!H32 -> 4.53 | H8: ='inventory2022 (FINAL)'!I32 -> 37.972
A9: 2 | B9: Balabac | C9: 2 | D9: =SUM(E9:H9) -> 18.5 | E9: ='inventory2022 (FINAL)'!F37 -> 17.81 | F9: ='inventory2022 (FINAL)'!G37 -> 0 | G9: ='inventory2022 (FINAL)'!H37 -> 0 | H9: ='inventory2022 (FINAL)'!I37 -> 0.69
A10: 3 | B10: Bataraza | C10: 14 | D10: =SUM(E10:H10) -> 49.3 | E10: ='inventory2022 (FINAL)'!F54 -> 4.56 | F10: ='inventory2022 (FINAL)'!G54 -> 0 | G10: ='inventory2022 (FINAL)'!H54 -> 0 | H10: ='inventory2022 (FINAL)'!I54 -> 44.74
A11: 4 | B11: Brooke's Point | C11: 32 | D11: =SUM(E11:H11) -> 107.85 | E11: ='inventory2022 (FINAL)'!F88 -> 41.619 | F11: ='inventory2022 (FINAL)'!G88 -> 0 | G11: ='inventory2022 (FINAL)'!H88 -> 0 | H11: ='inventory2022 (FINAL)'!I88 -> 66.231
A12: 5 | B12: Narra | C12: 27 | D12: =SUM(E12:H12) -> 102.5 | E12: ='inventory2022 (FINAL)'!F118 -> 29.04 | F12: ='inventory2022 (FINAL)'!G118 -> 0 | G12: ='inventory2022 (FINAL)'!H118 -> 0 | H12: ='inventory2022 (FINAL)'!I118 -> 73.46
A13: 6 | B13: Quezon | C13: 7 | D13: =SUM(E13:H13) -> 42.45 | E13: ='inventory2022 (FINAL)'!F128 -> 5.72 | F13: ='inventory2022 (FINAL)'!G128 -> 0 | G13: ='inventory2022 (FINAL)'!H128 -> 0 | H13: ='inventory2022 (FINAL)'!I128 -> 36.73
A14: 7 | B14: Rizal | C14: 1 | D14: =SUM(E14:H14) -> 3.1 | E14: ='inventory2022 (FINAL)'!F132 -> 0.48 | F14: ='inventory2022 (FINAL)'!G132 -> 0 | G14: ='inventory2022 (FINAL)'!H132 -> 0 | H14: ='inventory2022 (FINAL)'!I132 -> 2.62
A15: 8 | B15: Sofronio Española | C15: 10 | D15: =SUM(E15:H15) -> 54.1 | E15: ='inventory2022 (FINAL)'!F145 -> 15.85 | F15: ='inventory2022 (FINAL)'!G145 -> 0 | G15: ='inventory2022 (FINAL)'!H145 -> 0 | H15: ='inventory2022 (FINAL)'!I145 -> 38.25
A16: SOUTH SUB-TOTAL | C16: =SUM(C8:C15) -> 117 | D16: =SUM(D8:D15) -> 476.35 | E16: =SUM(E8:E15) -> 171.127 | F16: =SUM(F8:F15) -> 0 | G16: =SUM(G8:G15) -> 4.53 | H16: =SUM(H8:H15) -> 300.693 | I16: =SUM(E16:H16) -> 476.35
A17: 9 | B17: Agutaya | C17: 2 | D17: =SUM(E17:H17) -> 7.25 | E17: ='inventory2022 (FINAL)'!F150 -> 3.3 | F17: ='inventory2022 (FINAL)'!G150 -> 0 | G17: ='inventory2022 (FINAL)'!H150 -> 0 | H17: ='inventory2022 (FINAL)'!I150 -> 3.95
A18: 10 | B18: Araceli | C18: 11 | D18: =SUM(E18:H18) -> 62 | E18: ='inventory2022 (FINAL)'!F164 -> 12.194 | F18: ='inventory2022 (FINAL)'!G164 -> 0 | G18: ='inventory2022 (FINAL)'!H164 -> 0 | H18: ='inventory2022 (FINAL)'!I164 -> 49.806
A19: 11 | B19: Busuanga | C19: 8 | D19: =SUM(E19:H19) -> 42.084 | E19: ='inventory2022 (FINAL)'!F175 -> 1.404 | F19: ='inventory2022 (FINAL)'!G175 -> 0 | G19: ='inventory2022 (FINAL)'!H175 -> 0 | H19: ='inventory2022 (FINAL)'!I175 -> 40.68
A20: 12 | B20: Cagayancillo | C20: 1 | D20: =SUM(E20:H20) -> 8.741 | E20: ='inventory2022 (FINAL)'!F179 -> 1.18 | F20: ='inventory2022 (FINAL)'!G179 -> 0 | G20: ='inventory2022 (FINAL)'!H179 -> 0 | H20: ='inventory2022 (FINAL)'!I179 -> 7.561
A21: 13 | B21: Coron | C21: 13 | D21: =SUM(E21:H21) -> 116.96 | E21: ='inventory2022 (FINAL)'!F195 -> 57.31 | F21: ='inventory2022 (FINAL)'!G195 -> 0 | G21: ='inventory2022 (FINAL)'!H195 -> 3.42 | H21: ='inventory2022 (FINAL)'!I195 -> 56.23
A22: 14 | B22: Culion | C22: 4 | D22: =SUM(E22:H22) -> 28.0002 | E22: ='inventory2022 (FINAL)'!F202 -> 17.1412 | F22: ='inventory2022 (FINAL)'!G202 -> 0 | G22: ='inventory2022 (FINAL)'!H202 -> 0 | H22: ='inventory2022 (FINAL)'!I202 -> 10.859
A23: 15 | B23: Cuyo | C23: 8 | D23: =SUM(E23:H23) -> 49 | E23: ='inventory2022 (FINAL)'!F213 -> 26.39 | F23: ='inventory2022 (FINAL)'!G213 -> 5.143 | G23: ='inventory2022 (FINAL)'!H213 -> 0.1 | H23: ='inventory2022 (FINAL)'!I213 -> 17.367
A24: 16 | B24: Dumaran | C24: 14 | D24: =SUM(E24:H24) -> 74.19 | E24: ='inventory2022 (FINAL)'!F230 -> 26.14 | F24: ='inventory2022 (FINAL)'!G230 -> 0 | G24: ='inventory2022 (FINAL)'!H230 -> 0 | H24: ='inventory2022 (FINAL)'!I230 -> 48.05
A25: 17 | B25: El Nido | C25: 5 | D25: =SUM(E25:H25) -> 28.124 | E25: ='inventory2022 (FINAL)'!F238 -> 13.035 | F25: ='inventory2022 (FINAL)'!G238 -> 0 | G25: ='inventory2022 (FINAL)'!H238 -> 0 | H25: ='inventory2022 (FINAL)'!I238 -> 15.089
A26: 18 | B26: Magsaysay | C26: 11 | D26: =SUM(E26:H26) -> 35.78 | E26: ='inventory2022 (FINAL)'!F252 -> 19.316 | F26: ='inventory2022 (FINAL)'!G252 -> 5.6 | G26: ='inventory2022 (FINAL)'!H252 -> 0.914 | H26: ='inventory2022 (FINAL)'!I252 -> 9.95
A27: 19 | B27: Roxas | C27: 17 | D27: =SUM(E27:H27) -> 129.171 | E27: ='inventory2022 (FINAL)'!F272 -> 37.722 | F27: ='inventory2022 (FINAL)'!G272 -> 0 | G27: ='inventory2022 (FINAL)'!H272 -> 0 | H27: ='inventory2022 (FINAL)'!I272 -> 91.449
A28: 20 | B28: San Vicente | C28: 8 | D28: =SUM(E28:H28) -> 87.301 | E28: ='inventory2022 (FINAL)'!F283 -> 35.896 | F28: ='inventory2022 (FINAL)'!G283 -> 0 | G28: ='inventory2022 (FINAL)'!H283 -> 0 | H28: ='inventory2022 (FINAL)'!I283 -> 51.405
A29: 21 | B29: Taytay | C29: 8 | D29: =SUM(E29:H29) -> 84.6 | E29: ='inventory2022 (FINAL)'!F294 -> 18.353 | F29: ='inventory2022 (FINAL)'!G294 -> 0 | G29: ='inventory2022 (FINAL)'!H294 -> 1.72 | H29: ='inventory2022 (FINAL)'!I294 -> 64.527
A30: NORTH SUB-TOTAL | C30: =SUM(C17:C29) -> 110 | D30: =SUM(D17:D29) -> 753.2012 | E30: =SUM(E17:E29) -> 269.3812 | F30: =SUM(F17:F29) -> 10.743 | G30: =SUM(G17:G29) -> 6.154 | H30: =SUM(H17:H29) -> 466.923 | I30: =SUM(E30:H30) -> 753.2012
A31: GRANT TOTAL (SOUTH & NORTH) | C31: =C16+C30 -> 227 | D31: =D16+D30 -> 1229.5512 | E31: =E16+E30 -> 440.5082 | F31: =F16+F30 -> 10.743 | G31: =G16+G30 -> 10.684 | H31: =H16+H30 -> 767.616 | I31: =I30+I16 -> 1229.5512 | J31: =SUM(E31:H31) -> 1229.5512
A33: SUMMARY OF ROAD CONDITION
A35: NO | B35: ROAD CONDITION | C35: TOTAL LENGTH (KM) | E35: SUMMARY OF GOOD TO FAIR / POOR TO BAD ROAD CONDITION | K35: aborlan | L35: balabac | M35: bataraza | N35: brookes point | O35: narra | P35: quezon | Q35: rizal | R35: sofronio española | S35: agutaya | T35: araceli | U35: busuanga | V35: cagayancillo | W35: coron | X35: culion | Y35: cuyo | Z35: dumaran | AA35: el nido | AB35: magsaysay | AC35: roxas | AD35: san vicente | AE35: taytay | AF35: total
A36: 1 | B36: Good | C36: =AF36 -> 299.65 | E36: GOOD TO FAIR | H36: =C36+C37 -> 932.335 | J36: Good | K36: =SUMIF('inventory2022 (FINAL)'!J8:J31,"Good",'inventory2022 (FINAL)'!E8:E31) -> 36 | L36: =SUMIF('inventory2022 (FINAL)'!$J$35:$J$36,"Good",'inventory2022 (FINAL)'!$E$35:$E$36) -> 12.9 | M36: =SUMIF('inventory2022 (FINAL)'!$J$40:$J$53,"Good",'inventory2022 (FINAL)'!$E$40:$E$53) -> 1.3 | N36: =SUMIF('inventory2022 (FINAL)'!$J$56:$J$87,"Good",'inventory2022 (FINAL)'!$E$56:$E$87) -> 19.5 | O36: =SUMIF('inventory2022 (FINAL)'!$J$91:$J$117,"Good",'inventory2022 (FINAL)'!$E$91:$E$117) -> 16.9 | P36: =SUMIF('inventory2022 (FINAL)'!$J$121:$J$127,"Good",'inventory2022 (FINAL)'!$E$121:$E$127) -> 0 | Q36: =SUMIF('inventory2022 (FINAL)'!$J$131,"Good",'inventory2022 (FINAL)'!$E$131) -> 0 | R36: =SUMIF('inventory2022 (FINAL)'!$J$135:$J$144,"Good",'inventory2022 (FINAL)'!$E$135:$E$144) -> 7.2 | S36: =SUMIF('inventory2022 (FINAL)'!$J$148:$J$149,"Good",'inventory2022 (FINAL)'!$E$148:$E$149) -> 0 | T36: =SUMIF('inventory2022 (FINAL)'!$J$153:$J$163,"Good",'inventory2022 (FINAL)'!$E$153:$E$163) -> 0 | U36: =SUMIF('inventory2022 (FINAL)'!$J$167:$J$174,"Good",'inventory2022 (FINAL)'!$E$167:$E$174) -> 7.6 | V36: =SUMIF('inventory2022 (FINAL)'!$J$178,"Good",'inventory2022 (FINAL)'!$E$178) -> 0 | W36: =SUMIF('inventory2022 (FINAL)'!$J$182:$J$194,"Good",'inventory2022 (FINAL)'!$E$182:$E$194) -> 53.6 | X36: =SUMIF('inventory2022 (FINAL)'!$J$198:$J$201,"Good",'inventory2022 (FINAL)'!$E$198:$E$201) -> 17 | Y36: =SUMIF('inventory2022 (FINAL)'!$J$205:$J$212,"Good",'inventory2022 (FINAL)'!$E$205:$E$212) -> 31.3 | Z36: =SUMIF('inventory2022 (FINAL)'!$J$216:$J$229,"Good",'inventory2022 (FINAL)'!$E$216:$E$229) -> 5 | AA36: =SUMIF('inventory2022 (FINAL)'!$J$233:$J$237,"Good",'inventory2022 (FINAL)'!$E$233:$E$237) -> 11 | AB36: =SUMIF('inventory2022 (FINAL)'!$J$241:$J$251,"Good",'inventory2022 (FINAL)'!$E$241:$E$251) -> 4.67 | AC36: =SUMIF('inventory2022 (FINAL)'!$J$255:$J$271,"Good",'inventory2022 (FINAL)'!$E$255:$E$271) -> 27.33 | AD36: =SUMIF('inventory2022 (FINAL)'!$J$275:$J$282,"Good",'inventory2022 (FINAL)'!$E$275:$E$282) -> 34.55 | AE36: =SUMIF('inventory2022 (FINAL)'!$J$286:$J$293,"Good",'inventory2022 (FINAL)'!$E$286:$E$293) -> 13.8 | AF36: =SUM(K36:AE36) -> 299.65
A37: 2 | B37: Fair | C37: =AF37 -> 632.685 | E37: POOR TO BAD | H37: =C38+C39 -> 311.68 | J37: Fair | K37: =SUMIF('inventory2022 (FINAL)'!J8:J31,"Fair",'inventory2022 (FINAL)'!E8:E31) -> 46.15 | L37: =SUMIF('inventory2022 (FINAL)'!$J$35:$J$36,"Fair",'inventory2022 (FINAL)'!$E$35:$E$36) -> 5.6 | M37: =SUMIF('inventory2022 (FINAL)'!$J$40:$J$53,"Fair",'inventory2022 (FINAL)'!$E$40:$E$53) -> 11.3 | N37: =SUMIF('inventory2022 (FINAL)'!$J$56:$J$87,"Fair",'inventory2022 (FINAL)'!$E$56:$E$87) -> 68.85 | O37: =SUMIF('inventory2022 (FINAL)'!$J$91:$J$117,"Fair",'inventory2022 (FINAL)'!$E$91:$E$117) -> 45.4 | P37: =SUMIF('inventory2022 (FINAL)'!$J$121:$J$127,"Fair",'inventory2022 (FINAL)'!$E$121:$E$127) -> 0 | Q37: =SUMIF('inventory2022 (FINAL)'!$J$131,"Fair",'inventory2022 (FINAL)'!$E$131) -> 0 | R37: =SUMIF('inventory2022 (FINAL)'!$J$135:$J$144,"Fair",'inventory2022 (FINAL)'!$E$135:$E$144) -> 12.3 | S37: =SUMIF('inventory2022 (FINAL)'!$J$148:$J$149,"Fair",'inventory2022 (FINAL)'!$E$148:$E$149) -> 7.25 | T37: =SUMIF('inventory2022 (FINAL)'!$J$153:$J$163,"Fair",'inventory2022 (FINAL)'!$E$153:$E$163) -> 10.1 | U37: =SUMIF('inventory2022 (FINAL)'!$J$167:$J$174,"Fair",'inventory2022 (FINAL)'!$E$167:$E$174) -> 32.904 | V37: =SUMIF('inventory2022 (FINAL)'!$J$178,"Fair",'inventory2022 (FINAL)'!$E$178) -> 8.741 | W37: =SUMIF('inventory2022 (FINAL)'!$J$182:$J$194,"Fair",'inventory2022 (FINAL)'!$E$182:$E$194) -> 63.16 | X37: =SUMIF('inventory2022 (FINAL)'!$J$198:$J$201,"Fair",'inventory2022 (FINAL)'!$E$198:$E$201) -> 11 | Y37: =SUMIF('inventory2022 (FINAL)'!$J$205:$J$212,"Fair",'inventory2022 (FINAL)'!$E$205:$E$212) -> 12.7 | Z37: =SUMIF('inventory2022 (FINAL)'!$J$216:$J$229,"Fair",'inventory2022 (FINAL)'!$E$216:$E$229) -> 61.9 | AA37: =SUMIF('inventory2022 (FINAL)'!$J$233:$J$237,"Fair",'inventory2022 (FINAL)'!$E$233:$E$237) -> 13.6 | AB37: =SUMIF('inventory2022 (FINAL)'!$J$241:$J$251,"Fair",'inventory2022 (FINAL)'!$E$241:$E$251) -> 7.96 | AC37: =SUMIF('inventory2022 (FINAL)'!$J$255:$J$271,"Fair",'inventory2022 (FINAL)'!$E$255:$E$271) -> 98.65 | AD37: =SUMIF('inventory2022 (FINAL)'!$J$275:$J$282,"Fair",'inventory2022 (FINAL)'!$E$275:$E$282) -> 47.62 | AE37: =SUMIF('inventory2022 (FINAL)'!$J$286:$J$293,"Fair",'inventory2022 (FINAL)'!$E$286:$E$293) -> 67.5 | AF37: =SUM(K37:AE37) -> 632.685
A38: 3 | B38: Poor | C38: =AF38 -> 196.92 | E38: GRAND TOTAL | H38: =SUM(H36:H37) -> 1244.015 | J38: Poor | K38: =SUMIF('inventory2022 (FINAL)'!J8:J31,"Poor",'inventory2022 (FINAL)'!E8:E31) -> 8.8 | L38: =SUMIF('inventory2022 (FINAL)'!$J$35:$J$36,"Poor",'inventory2022 (FINAL)'!$E$35:$E$36) -> 0 | M38: =SUMIF('inventory2022 (FINAL)'!$J$40:$J$53,"Poor",'inventory2022 (FINAL)'!$E$40:$E$53) -> 12.2 | N38: =SUMIF('inventory2022 (FINAL)'!$J$56:$J$87,"Poor",'inventory2022 (FINAL)'!$E$56:$E$87) -> 19.5 | O38: =SUMIF('inventory2022 (FINAL)'!$J$91:$J$117,"Poor",'inventory2022 (FINAL)'!$E$91:$E$117) -> 18.7 | P38: =SUMIF('inventory2022 (FINAL)'!$J$121:$J$127,"Poor",'inventory2022 (FINAL)'!$E$121:$E$127) -> 25.45 | Q38: =SUMIF('inventory2022 (FINAL)'!$J$131,"Poor",'inventory2022 (FINAL)'!$E$131) -> 3.1 | R38: =SUMIF('inventory2022 (FINAL)'!$J$135:$J$144,"Poor",'inventory2022 (FINAL)'!$E$135:$E$144) -> 26.8 | S38: =SUMIF('inventory2022 (FINAL)'!$J$148:$J$149,"Poor",'inventory2022 (FINAL)'!$E$148:$E$149) -> 0 | T38: =SUMIF('inventory2022 (FINAL)'!$J$153:$J$163,"Poor",'inventory2022 (FINAL)'!$E$153:$E$163) -> 48.7 | U38: =SUMIF('inventory2022 (FINAL)'!$J$167:$J$174,"Poor",'inventory2022 (FINAL)'!$E$167:$E$174) -> 0 | V38: =SUMIF('inventory2022 (FINAL)'!$J$178,"Poor",'inventory2022 (FINAL)'!$E$178) -> 0 | W38: =SUMIF('inventory2022 (FINAL)'!$J$182:$J$194,"Poor",'inventory2022 (FINAL)'!$E$182:$E$194) -> 0.2 | X38: =SUMIF('inventory2022 (FINAL)'!$J$198:$J$201,"Poor",'inventory2022 (FINAL)'!$E$198:$E$201) -> 0 | Y38: =SUMIF('inventory2022 (FINAL)'!$J$205:$J$212,"Poor",'inventory2022 (FINAL)'!$E$205:$E$212) -> 0 | Z38: =SUMIF('inventory2022 (FINAL)'!$J$216:$J$229,"Poor",'inventory2022 (FINAL)'!$E$216:$E$229) -> 12 | AA38: =SUMIF('inventory2022 (FINAL)'!$J$233:$J$237,"Poor",'inventory2022 (FINAL)'!$E$233:$E$237) -> 0 | AB38: =SUMIF('inventory2022 (FINAL)'!$J$241:$J$251,"Poor",'inventory2022 (FINAL)'!$E$241:$E$251) -> 15.97 | AC38: =SUMIF('inventory2022 (FINAL)'!$J$255:$J$271,"Poor",'inventory2022 (FINAL)'!$E$255:$E$271) -> 0 | AD38: =SUMIF('inventory2022 (FINAL)'!$J$275:$J$282,"Poor",'inventory2022 (FINAL)'!$E$275:$E$282) -> 5.5 | AE38: =SUMIF('inventory2022 (FINAL)'!$J$286:$J$293,"Poor",'inventory2022 (FINAL)'!$E$286:$E$293) -> 0 | AF38: =SUM(K38:AE38) -> 196.92
A39: 4 | B39: Bad | C39: =AF39 -> 114.76 | J39: Bad | K39: =SUMIF('inventory2022 (FINAL)'!J8:J31,"Bad",'inventory2022 (FINAL)'!E8:E31) -> 7.6 | L39: =SUMIF('inventory2022 (FINAL)'!$J$35:$J$36,"Bad",'inventory2022 (FINAL)'!$E$35:$E$36) -> 0 | M39: =SUMIF('inventory2022 (FINAL)'!$J$40:$J$53,"Bad",'inventory2022 (FINAL)'!$E$40:$E$53) -> 24.5 | N39: =SUMIF('inventory2022 (FINAL)'!$J$56:$J$87,"Bad",'inventory2022 (FINAL)'!$E$56:$E$87) -> 0 | O39: =SUMIF('inventory2022 (FINAL)'!$J$91:$J$117,"Bad",'inventory2022 (FINAL)'!$E$91:$E$117) -> 21.5 | P39: =SUMIF('inventory2022 (FINAL)'!$J$121:$J$127,"Bad",'inventory2022 (FINAL)'!$E$121:$E$127) -> 17 | Q39: =SUMIF('inventory2022 (FINAL)'!$J$131,"Bad",'inventory2022 (FINAL)'!$E$131) -> 0 | R39: =SUMIF('inventory2022 (FINAL)'!$J$135:$J$144,"Bad",'inventory2022 (FINAL)'!$E$135:$E$144) -> 7.8 | S39: =SUMIF('inventory2022 (FINAL)'!$J$148:$J$149,"Bad",'inventory2022 (FINAL)'!$E$148:$E$149) -> 0 | T39: =SUMIF('inventory2022 (FINAL)'!$J$153:$J$163,"Bad",'inventory2022 (FINAL)'!$E$153:$E$163) -> 3.2 | U39: =SUMIF('inventory2022 (FINAL)'!$J$167:$J$174,"Bad",'inventory2022 (FINAL)'!$E$167:$E$174) -> 1.58 | V39: =SUMIF('inventory2022 (FINAL)'!$J$178,"Bad",'inventory2022 (FINAL)'!$E$178) -> 0 | W39: =SUMIF('inventory2022 (FINAL)'!$J$182:$J$194,"Bad",'inventory2022 (FINAL)'!$E$182:$E$194) -> 0 | X39: =SUMIF('inventory2022 (FINAL)'!$J$198:$J$201,"Bad",'inventory2022 (FINAL)'!$E$198:$E$201) -> 0 | Y39: =SUMIF('inventory2022 (FINAL)'!$J$205:$J$212,"Bad",'inventory2022 (FINAL)'!$E$205:$E$212) -> 5 | Z39: =SUMIF('inventory2022 (FINAL)'!$J$216:$J$229,"Bad",'inventory2022 (FINAL)'!$E$216:$E$229) -> 9.7 | AA39: =SUMIF('inventory2022 (FINAL)'!$J$233:$J$237,"Bad",'inventory2022 (FINAL)'!$E$233:$E$237) -> 3 | AB39: =SUMIF('inventory2022 (FINAL)'!$J$241:$J$251,"Bad",'inventory2022 (FINAL)'!$E$241:$E$251) -> 7.18 | AC39: =SUMIF('inventory2022 (FINAL)'!$J$255:$J$271,"Bad",'inventory2022 (FINAL)'!$E$255:$E$271) -> 3.4 | AD39: =SUMIF('inventory2022 (FINAL)'!$J$275:$J$282,"Bad",'inventory2022 (FINAL)'!$E$275:$E$282) -> 0 | AE39: =SUMIF('inventory2022 (FINAL)'!$J$286:$J$293,"Bad",'inventory2022 (FINAL)'!$E$286:$E$293) -> 3.3 | AF39: =SUM(K39:AE39) -> 114.76
A40: GRAND TOTAL | C40: =SUM(C36:C39) -> 1244.015 | K40: =SUM(K36:K39) -> 98.55 | L40: =SUM(L36:L39) -> 18.5 | M40: =SUM(M36:M39) -> 49.3 | N40: =SUM(N36:N39) -> 107.85 | O40: =SUM(O36:O39) -> 102.5 | P40: =SUM(P36:P39) -> 42.45 | Q40: =SUM(Q36:Q39) -> 3.1 | R40: =SUM(R36:R39) -> 54.1 | ... AF40: =SUM(AF36:AF39) -> 1244.015
B43: Prepared by: | E43: Reviewed by:
K44: CONCRETE (KM) | L44: ASPHALT (KM) | M44: EARTH (KM) | N44: GRAVEL (KM)
J45: Good | K45: =SUMIF('inventory2022 (FINAL)'!$J$8:$J$294,"Good",'inventory2022 (FINAL)'!$F$8:$F$294) -> 221.1882 | L45: =SUMIF('inventory2022 (FINAL)'!$J$8:$J$294,"Good",'inventory2022 (FINAL)'!$G$8:$G$294) -> 2.083 | M45: =SUMIF('inventory2022 (FINAL)'!$J$8:$J$294,"Good",'inventory2022 (FINAL)'!$H$8:$H$294) -> 3.42 | N45: =SUMIF('inventory2022 (FINAL)'!$J$8:$J$294,"Good",'inventory2022 (FINAL)'!$I$8:$I$294) -> 76.466 | O45: =SUM(K45:N45) -> 303.1572
B46: CHARISMA WY A. BOLEN | E46: RANFORD T. VILLEGAS | J46: Fair | K46: =SUMIF('inventory2022 (FINAL)'!$J$8:$J$294,"Fair",'inventory2022 (FINAL)'!$F$8:$F$294) -> 171.764 | L46: =SUMIF('inventory2022 (FINAL)'!$J$8:$J$294,"Fair",'inventory2022 (FINAL)'!$G$8:$G$294) -> 0 | M46: =SUMIF('inventory2022 (FINAL)'!$J$8:$J$294,"Fair",'inventory2022 (FINAL)'!$H$8:$H$294) -> 1.72 | N46: =SUMIF('inventory2022 (FINAL)'!$J$8:$J$294,"Fair",'inventory2022 (FINAL)'!$I$8:$I$294) -> 450.972 | O46: =SUM(K46:N46) -> 624.456
...

Sheet Indicator 5
A1: Capacity Element 3: Information and resources for local road management | G1: pw: lrmpat2020
B3: Indicator 5: Annual budget for road rehabilitation
B4: Please fill up the table that follows with information on length of local core roads for the last three years
B6: For Core Roads in Gravel
B7: Year | C7: Total Length of Core Roads (a) | D7: Thickness of Road in mm | E7: Cost of rehabilitation based on thickness | F7: Ideal (Required) Budget | G7: Actual Budget for Road Rehabilitation based on Appropriation Ordinance | H7: % of Budget against Requirement
A8: 2021 | B8: Current Year | D8: 150 | E8: =IF(D8=150, 4572000, IF(D8=200, 4851000)) -> 4572000 | F8: =C8*E8 -> 0 | H8: =IF(C8="","",(G8/F8 * 100)) | K8: =OR(C8>=1,C9>=1,C10>=1) -> FALSE | L8: =IF(K8=TRUE,1,0) -> 0 | M8: =C8>=1 -> FALSE | N8: =IF(M8=TRUE,1,0) -> 0
A9: 2020 | B9: Prior Year | D9: 150 | E9: =IF(D9=150, 4572000, IF(D9=200, 4851000)) -> 4572000 | F9: =C9*E9 -> 0 | H9: =IF(C9="","",(G9/F9 * 100)) | M9: =C9>=1 -> FALSE | N9: =IF(M9=TRUE,1,0) -> 0
A10: 2019 | B10: Two Years Prior | D10: 150 | E10: =IF(D10=150, 4572000, IF(D10=200, 4851000)) -> 4572000 | F10: =C10*E10 -> 0 | H10: =IF(C10="","",(G10/F10 * 100)) | M10: =C10>=1 -> FALSE | N10: =IF(M10=TRUE,1,0) -> 0
G11: Average | H11: =IF(AND(C8="",C9="",C10=""),"",(SUM(H8:H10)/SUM(N8:N10)))
G13: Score for Gravel only | H13: =IF(L8=0,0,(IF(H11 >=100, 4, IF(H11 >=80, 3, IF(H11 >=60, 2, IF(H11 >=40, 1, 0)))))) -> 0
B15: For Core Roads in Asphalt
B16: Year | C16: Total Length of Core Roads | D16: Thickness of Road in mm | E16: Cost of rehabilitation based on thickness | F16: Ideal (Required) Budget | G16: Actual Budget for Road Rehabilitation based on Appropriation Ordinance | H16: % of Budget against Requirement
A17: 2021 | B17: Current Year | D17: 50 | E17: =IF(D17=50, 6591000) -> 6591000 | F17: =C17*E17 -> 0 | H17: =IF(C17="","",(G17/F17 * 100)) | K17: =OR(C17>=1,C18>=1,C19>=1) -> FALSE | L17: =IF(K17=TRUE,1,0) -> 0 | M17: =C17>=1 -> FALSE | N17: =IF(M17=TRUE,1,0) -> 0
A18: 2020 | B18: Prior Year | D18: 50 | E18: =IF(D18=50, 6591000) -> 6591000 | F18: =C18*E18 -> 0 | H18: =IF(C18="","",(G18/F18 * 100)) | M18: =C18>=1 -> FALSE | N18: =IF(M18=TRUE,1,0) -> 0
A19: 2019 | B19: Two Years Prior | D19: 50 | E19: =IF(D19=50, 6591000) -> 6591000 | F19: =C19*E19 -> 0 | H19: =IF(C19="","",(G19/F19 * 100)) | M19: =C19>=1 -> FALSE | N19: =IF(M19=TRUE,1,0) -> 0
G20: Average | H20: =IF(AND(C17="",C18="",C19=""),"",(SUM(H17:H19)/SUM(N17:N19)))
G22: Score for Asphalt only | H22: =IF(L17=0,0,IF(AND(C26="",C17="",C8=""),0,(IF(H20 >=100, 4, IF(H20 >=80, 3, IF(H20 >=60, 2, IF(H20 >=40, 1, 0))))))) -> 0
B24: For Core Roads in PCCP
B25: Year | C25: Total Length of Core Roads (a) | D25: Thickness of Road in mm | E25: Cost of rehabilitation based on thickness | F25: Ideal (Required) Budget | G25: Actual Budget for Road Rehabilitation based on Appropriation Ordinance | H25: % of Budget against Requirement
A26: 2021 | B26: Current Year | D26: 230 | E26: =IF(D26=150, 7487000, IF(D26=200, 9106000, IF(D26=230, 9847000))) -> 9847000 | F26: =C26*E26 -> 0 | G26: 970000000 | H26: =IF(C26="","",(G26/F26 * 100)) | K26: =OR(C26>=1,C27>=1,C28>=1) -> FALSE | L26: =IF(K26=TRUE,1,0) -> 0 | M26: =C26>=1 -> FALSE | N26: =IF(M26=TRUE,1,0) -> 0
A27: 2020 | B27: Prior Year | D27: 200 | E27: =IF(D27=150, 7487000, IF(D27=200, 9106000, IF(D27=230, 9847000))) -> 9106000 | F27: =C27*E27 -> 0 | G27: 810000000 | H27: =IF(C27="","",(G27/F27 * 100)) | M27: =C27>=1 -> FALSE | N27: =IF(M27=TRUE,1,0) -> 0
A28: 2019 | B28: Two Years Prior | D28: 150 | E28: =IF(D28=150, 7487000, IF(D28=200, 9106000, IF(D28=230, 9847000))) -> 7487000 | F28: =C28*E28 -> 0 | G28: 590000000 | H28: =IF(C28="","",(G28/F28 * 100)) | M28: =C28>=1 -> FALSE | N28: =IF(M28=TRUE,1,0) -> 0
G29: Average | H29: =IF(AND(C26="",C27="",C28=""),"",(SUM(H26:H28)/SUM(N26:N28)))
G31: Sore for PCCP only | H31: =IF(L26=0,0,(IF(H29 >=100, 4, IF(H29 >=80, 3, IF(H29 >=60, 2, IF(H29 >=40, 1, 0)))))) -> 0
B32: Average of all surfaces
B33: Surface | C33: Three-year average
B34: Gravel | C34: =IF(AND(C8="",C9="",C10=""),"",H11)
B35: Asphalt | C35: =IF(AND(C17="",C18="",C19=""),"",H20)
B36: PCCP | C36: =IF(AND(C26="",C27="",C28=""),"",H29)
B37: Average | C37: =IF(AND(C26="",C17="",C8=""),0,(SUM(C34:C36)/SUM(L8,L17,L26))) -> 0
B39: Score | C39: =IF(C37 >=100, 4, IF(C37 >=80, 3, IF(C37 >=60, 2, IF(C37 >=40, 1, 0)))) -> 0
B41: Notes/Annotations:
B53: Score is 4 if percentage is 100 or more.
B54: Score is 3 if percentage is at least 80.
B55: Score is 2 if percentage is at least 60.
B56: Score is 1 if percentage is at least 40.
B57: Score is 0 if percentage is at least 20.

Sheet inventory2019(FOR UPDATE)
A1: PROVINCIAL ENGINEER'S OFFICE
A2: PROVINCIAL ROAD NETWORK AND ITS STATUS / CONDITION
A3: 2019
A4: MUNICIPALITY OF ABORLAN
A6: ROAD ID | B6: ROAD NAME | C6: REVISED LENGTH (km/s.) | D6: OLD LENGTH | E6: SURFACE TYPE | J6: ROAD CONDITION | K6: KILOMETER POST | L6: REMARKS
E7: CONCRETE | F7: ASPHALT | G7: EARTH | H7: GRAVEL | I7: MIXED
A8: 219 | B8: Junction - Isaub Road | C8: =SUM(E8:I8) -> 0.4 | D8: ='[23]road inventory 2018'!C10 -> 0.65 | E8: 0 | F8: 0 | G8: 0 | H8: 0.4 | I8: 0 | J8: Fair | K8: km sta.57+800
A9: 1 | B9: Sagpangan Road | C9: =SUM(E9:I9) -> 5.48 | D9: ='[23]road inventory 2018'!C11 -> 5.5 | E9: 2.87 | F9: 0 | G9: 0 | H9: 2.61 | I9: 0 | J9: Fair | K9: km sta.66+400
A10: 2 | B10: Isaub - Marikit -Tubig Road | C10: =SUM(E10:I10) -> 0.92 | D10: ='[23]road inventory 2018'!C12 -> 0.8 | E10: 0.07 | F10: 0 | G10: 0 | H10: 0.85 | I10: 0 | J10: Good | K10: km sta.58+000
A11: 3 | B11: Mailigan - Sagpangan Road | C11: =SUM(E11:I11) -> 4.97 | D11: ='[23]road inventory 2018'!C13 -> 4.9 | E11: 0 | F11: 0 | G11: 0 | H11: 4.97 | I11: 0 | J11: Fair | K11: km sta.62+400
A12: 4 | B12: Iraan - Tubig Road | C12: =SUM(E12:I12) -> 2.67 | D12: ='[23]road inventory 2018'!C14 -> 2.7 | E12: 0.11 | F12: 0 | G12: 0 | H12: 2.56 | I12: 0 | J12: Poor | K12: km sta.64+900
A13: 93 | B13: Iraan - Baraki Road | C13: =SUM(E13:I13) -> 3.9 | D13: ='[23]road inventory 2018'!C15 -> 3.9 | E13: 3.9 | F13: 0 | G13: 0 | H13: 0 | I13: 0 | J13: =#REF! -> #REF! | K13: km sta.64+900
A14: 218 | B14: Isaub - Sagpangan Road | C14: =SUM(E14:I14) -> 5.61 | D14: ='[23]road inventory 2018'!C16 -> 5.8 | E14: 0 | F14: 0 | G14: 0 | H14: 5.61 | I14: 0 | J14: Fair | K14: km sta.58+000
A15: 5 | B15: PNAC Road | C15: =SUM(E15:I15) -> 2.85 | D15: ='[23]road inventory 2018'!C17 -> 2.8 | E15: 2.85 | F15: 0 | G15: 0 | H15: 0 | I15: 0 | J15: Good | K15: km sta.64+900
A16: 6 | B16: San Juan Road | C16: =SUM(E16:I16) -> 3.96 | D16: ='[23]road inventory 2018'!C18 -> 3.9 | E16: 2.7 | F16: 0 | G16: 0 | H16: 1.26 | I16: 0 | J16: Good | K16: km sta.66+400
A17: 7 | B17: Aborlan - River Landing | C17: =SUM(E17:I17) -> 1.15 | D17: ='[23]road inventory 2018'!C19 -> 1.1 | E17: 1.15 | F17: 0 | G17: 0 | H17: 0 | I17: 0 | J17: Good | K17: km sta.67+100
A18: 8 | B18: Aborlan Poblacion Road | C18: =SUM(E18:I18) -> 0.64 | D18: ='[23]road inventory 2018'!C20 -> 0.6 | E18: 0.64 | F18: 0 | G18: 0 | H18: 0 | I18: 0 | J18: Good | K18: km sta.66+950
A19: 9 | B19: Magbabadil - Cabigaan Road | C19: =SUM(E19:I19) -> 9.3 | D19: ='[23]road inventory 2018'!C21 -> 9 | E19: 9.3 | F19: 0 | G19: 0 | H19: 0 | I19: 0 | J19: Good | K19: km sta.66+800
A20: 10 | B20: Plaridel - Apis Cabigaan Road | C20: =SUM(E20:I20) -> 13.79 | D20: ='[23]road inventory 2018'!C22 -> 13.6 | E20: 8.79 | F20: 0 | G20: 0 | H20: 5 | I20: 0 | J20: =J19 -> Good | K20: km sta.75+650
A21: 11 | B21: Tagpait Feeder Road | C21: =SUM(E21:I21) -> 2.27 | D21: ='[23]road inventory 2018'!C23 -> 2.2 | E21: 0.21 | F21: 0 | G21: 0 | H21: 2.06 | I21: 0 | J21: Fair | K21: km sta.69+000
A22: 13 | B22: New Bantayan - Apis Road | C22: =SUM(E22:I22) -> 1.72 | D22: ='[23]road inventory 2018'!C24 -> 1.7 | E22: 0 | F22: 0 | G22: 0 | H22: 1.72 | I22: 0 | J22: Fair | K22: km sta.69+200
A23: 12 | B23: Tagbariri Road | C23: =SUM(E23:I23) -> 1.62 | D23: ='[23]road inventory 2018'!C25 -> 1.6 | E23: 0 | F23: 0 | G23: 0 | H23: 1.62 | I23: 0 | J23: Poor | K23: km sta.69+100
A24: 220 | B24: Tagbariri - Magsaysay Road | C24: =SUM(E24:I24) -> 2.11 | D24: ='[23]road inventory 2018'!C26 -> 2.3 | E24: 0 | F24: 0 | G24: 0 | H24: 2.11 | I24: 0 | J24: Poor | K24: km sta.71+150
A25: 14 | B25: Junction - Tigman Road | C25: =SUM(E25:I25) -> 4.12 | D25: ='[23]road inventory 2018'!C27 -> 4 | E25: 4.12 | F25: 0 | G25: 0 | H25: 0 | I25: 0 | J25: Good | K25: km sta.75+650
A26: 15 | B26: Tigman - Rizal Road | C26: =SUM(E26:I26) -> 0 | D26: ='[23]road inventory 2018'!C28 -> 3.2 | E26: 0 | F26: 0 | G26: 0 | H26: 0 | I26: 0 | J26: Poor | K26: km sta.77+400 | L26: NOT EXISTING
A27: 16 | B27: Tigman - Caburian Road | C27: =SUM(E27:I27) -> 1.05 | D27: ='[23]road inventory 2018'!C29 -> 1 | E27: 0 | F27: 0 | G27: 0 | H27: 1.05 | I27: 0 | J27: Fair | K27: km sta.78+150
A28: 17 | B28: Magbabadil - Baraki Road | C28: =SUM(E28:I28) -> 4.18 | D28: ='[23]road inventory 2018'!C30 -> 4 | E28: 4.18 | F28: 0 | G28: 0 | H28: 0 | I28: 0 | J28: Fair | K28: km sta.73+400
A29: 18 | B29: Tigman - Rizal - Dumangueña Road | C29: =SUM(E29:I29) -> 10.52 | D29: ='[23]road inventory 2018'!C31 -> 10.5 | E29: 4.54 | F29: 0 | G29: 0 | H29: 5.98 | I29: 0 | J29: Fair | K29: km sta.77+400
A30: 221 | B30: Hi-way Jct. Plaridel-Tigman-Caburian Rd | C30: =SUM(E30:I30) -> 4.53 | D30: ='[23]road inventory 2018'!C32 -> 5.2 | E30: 0 | F30: 0 | G30: 0 | H30: 4.53 | I30: 0 | J30: Fair | K30: km sta.76+500
A31: 20 | B31: Aporawan-Daan-Cabigaan Road | C31: =SUM(E31:I31) -> 7.63 | D31: ='[23]road inventory 2018'!C33 -> 7.6 | E31: 0 | F31: 0 | G31: 0 | H31: 7.63 | I31: 0 | J31: Bad
